<?xml version="1.0" encoding="utf-8"?>
<robot xmlns:xacro="http://www.ros.org/wiki/xacro">

  <!-- The spine is attached to 'parent' and provides a mounting point for other components -->
  <xacro:macro name="franka_spine" params="parent">
    <joint name="franka_spine_fixed_joint" type="fixed">
      <parent link="${parent}"/>
      <child link="franka_spine"/>
      <origin xyz="0.138289 0.0 0.350" rpy="0 0 0"/>
    </joint>

    <link name="franka_spine_mounting_point">
      <inertial>
        <origin xyz="0 0 0" rpy="0 0 0"/>
        <mass value="0.01"/>
        <inertia ixx="0.0001" ixy="0.0" ixz="0.0" iyy="0.0001" iyz="0.0" izz="0.0001"/>
      </inertial>
    </link>

    <link name="franka_spine">
      <visual name="franka_spine_visual">
        <geometry>
          <mesh filename="package://franka_description/meshes/accessories/franka_spine_v0_1/visual/franka_spine.dae"/>
        </geometry>
      </visual>
      <collision name="franka_spine_collision">
        <geometry>
          <mesh filename="package://franka_description/meshes/accessories/franka_spine_v0_1/collision/franka_spine.stl"/>
        </geometry>
        <material name="red">
          <color rgba="1 0 0 1"/>
        </material>
      </collision>
      <inertial>
        <origin xyz="0.042358 0.000378 0.495198" rpy="0 0 0"/>
        <mass value="21.909124"/>
        <inertia ixx="3.338968145" ixy="-0.000642887" ixz="0.299962762" iyy="3.324560297" iyz="-0.004488422"
          izz="0.281489258"/>
      </inertial>
    </link>

    <joint name="franka_spine_vertical_joint" type="prismatic">
      <parent link="franka_spine"/>
      <child link="franka_spine_mounting_point"/>
      <origin xyz="0.266711 0.0 0.1" rpy="0 0 0"/>
      <axis xyz="0 0 1"/>
      <limit effort="100" lower="0.0" upper="0.85" velocity="0.1"/>
    </joint>

  </xacro:macro>

</robot>
